Internal Server Error: /
Traceback (most recent call last):
  File "/usr/local/lib/python3.13/urllib/request.py", line 1319, in do_open
    h.request(req.get_method(), req.selector, req.data, headers,
    ~~~~~~~~~^^^^^^^^^^^^^^^^^^^^^^^^^^^^^^^^^^^^^^^^^^^^^^^^^^^
              encode_chunked=req.has_header('Transfer-encoding'))
              ^^^^^^^^^^^^^^^^^^^^^^^^^^^^^^^^^^^^^^^^^^^^^^^^^^^
  File "/usr/local/lib/python3.13/http/client.py", line 1336, in request
    self._send_request(method, url, body, headers, encode_chunked)
    ~~~~~~~~~~~~~~~~~~^^^^^^^^^^^^^^^^^^^^^^^^^^^^^^^^^^^^^^^^^^^^
  File "/usr/local/lib/python3.13/http/client.py", line 1382, in _send_request
    self.endheaders(body, encode_chunked=encode_chunked)
    ~~~~~~~~~~~~~~~^^^^^^^^^^^^^^^^^^^^^^^^^^^^^^^^^^^^^
  File "/usr/local/lib/python3.13/http/client.py", line 1331, in endheaders
    self._send_output(message_body, encode_chunked=encode_chunked)
    ~~~~~~~~~~~~~~~~~^^^^^^^^^^^^^^^^^^^^^^^^^^^^^^^^^^^^^^^^^^^^^
  File "/usr/local/lib/python3.13/http/client.py", line 1091, in _send_output
    self.send(msg)
    ~~~~~~~~~^^^^^
  File "/usr/local/lib/python3.13/http/client.py", line 1035, in send
    self.connect()
    ~~~~~~~~~~~~^^
  File "/usr/local/lib/python3.13/http/client.py", line 1470, in connect
    super().connect()
    ~~~~~~~~~~~~~~~^^
  File "/usr/local/lib/python3.13/http/client.py", line 1001, in connect
    self.sock = self._create_connection(
                ~~~~~~~~~~~~~~~~~~~~~~~^
        (self.host,self.port), self.timeout, self.source_address)
        ^^^^^^^^^^^^^^^^^^^^^^^^^^^^^^^^^^^^^^^^^^^^^^^^^^^^^^^^^
  File "/usr/local/lib/python3.13/socket.py", line 840, in create_connection
    for res in getaddrinfo(host, port, 0, SOCK_STREAM):
               ~~~~~~~~~~~^^^^^^^^^^^^^^^^^^^^^^^^^^^^
  File "/usr/local/lib/python3.13/socket.py", line 975, in getaddrinfo
    for res in _socket.getaddrinfo(host, port, family, type, proto, flags):
               ~~~~~~~~~~~~~~~~~~~^^^^^^^^^^^^^^^^^^^^^^^^^^^^^^^^^^^^^^^^
socket.gaierror: [Errno -3] Temporary failure in name resolution

During handling of the above exception, another exception occurred:

Traceback (most recent call last):
  File "/home/igor/Documents/code/projects/erstehaus/.venv/lib/python3.13/site-packages/geopy/adapters.py", line 298, in get_text
    page = self.urlopen(req, timeout=timeout)
  File "/usr/local/lib/python3.13/urllib/request.py", line 489, in open
    response = self._open(req, data)
  File "/usr/local/lib/python3.13/urllib/request.py", line 506, in _open
    result = self._call_chain(self.handle_open, protocol, protocol +
                              '_open', req)
  File "/usr/local/lib/python3.13/urllib/request.py", line 466, in _call_chain
    result = func(*args)
  File "/usr/local/lib/python3.13/urllib/request.py", line 1367, in https_open
    return self.do_open(http.client.HTTPSConnection, req,
           ~~~~~~~~~~~~^^^^^^^^^^^^^^^^^^^^^^^^^^^^^^^^^^
                        context=self._context)
                        ^^^^^^^^^^^^^^^^^^^^^^
  File "/usr/local/lib/python3.13/urllib/request.py", line 1322, in do_open
    raise URLError(err)
urllib.error.URLError: <urlopen error [Errno -3] Temporary failure in name resolution>

During handling of the above exception, another exception occurred:

Traceback (most recent call last):
  File "/home/igor/Documents/code/projects/erstehaus/.venv/lib/python3.13/site-packages/django/core/handlers/exception.py", line 55, in inner
    response = get_response(request)
  File "/home/igor/Documents/code/projects/erstehaus/.venv/lib/python3.13/site-packages/django/core/handlers/base.py", line 197, in _get_response
    response = wrapped_callback(request, *callback_args, **callback_kwargs)
  File "/home/igor/Documents/code/projects/erstehaus/home/views.py", line 33, in home
    lat, lon = get_office_coordinates()
               ~~~~~~~~~~~~~~~~~~~~~~^^
  File "/home/igor/Documents/code/projects/erstehaus/home/views.py", line 26, in get_office_coordinates
    location = geolocator.geocode(page_content.address)
  File "/home/igor/Documents/code/projects/erstehaus/.venv/lib/python3.13/site-packages/geopy/geocoders/nominatim.py", line 297, in geocode
    return self._call_geocoder(url, callback, timeout=timeout)
           ~~~~~~~~~~~~~~~~~~~^^^^^^^^^^^^^^^^^^^^^^^^^^^^^^^^
  File "/home/igor/Documents/code/projects/erstehaus/.venv/lib/python3.13/site-packages/geopy/geocoders/base.py", line 368, in _call_geocoder
    result = self.adapter.get_json(url, timeout=timeout, headers=req_headers)
  File "/home/igor/Documents/code/projects/erstehaus/.venv/lib/python3.13/site-packages/geopy/adapters.py", line 287, in get_json
    text = self.get_text(url, timeout=timeout, headers=headers)
  File "/home/igor/Documents/code/projects/erstehaus/.venv/lib/python3.13/site-packages/geopy/adapters.py", line 324, in get_text
    raise GeocoderServiceError(message)
geopy.exc.GeocoderServiceError: [Errno -3] Temporary failure in name resolution
Internal Server Error: /
Traceback (most recent call last):
  File "/usr/local/lib/python3.13/urllib/request.py", line 1319, in do_open
    h.request(req.get_method(), req.selector, req.data, headers,
    ~~~~~~~~~^^^^^^^^^^^^^^^^^^^^^^^^^^^^^^^^^^^^^^^^^^^^^^^^^^^
              encode_chunked=req.has_header('Transfer-encoding'))
              ^^^^^^^^^^^^^^^^^^^^^^^^^^^^^^^^^^^^^^^^^^^^^^^^^^^
  File "/usr/local/lib/python3.13/http/client.py", line 1336, in request
    self._send_request(method, url, body, headers, encode_chunked)
    ~~~~~~~~~~~~~~~~~~^^^^^^^^^^^^^^^^^^^^^^^^^^^^^^^^^^^^^^^^^^^^
  File "/usr/local/lib/python3.13/http/client.py", line 1382, in _send_request
    self.endheaders(body, encode_chunked=encode_chunked)
    ~~~~~~~~~~~~~~~^^^^^^^^^^^^^^^^^^^^^^^^^^^^^^^^^^^^^
  File "/usr/local/lib/python3.13/http/client.py", line 1331, in endheaders
    self._send_output(message_body, encode_chunked=encode_chunked)
    ~~~~~~~~~~~~~~~~~^^^^^^^^^^^^^^^^^^^^^^^^^^^^^^^^^^^^^^^^^^^^^
  File "/usr/local/lib/python3.13/http/client.py", line 1091, in _send_output
    self.send(msg)
    ~~~~~~~~~^^^^^
  File "/usr/local/lib/python3.13/http/client.py", line 1035, in send
    self.connect()
    ~~~~~~~~~~~~^^
  File "/usr/local/lib/python3.13/http/client.py", line 1470, in connect
    super().connect()
    ~~~~~~~~~~~~~~~^^
  File "/usr/local/lib/python3.13/http/client.py", line 1001, in connect
    self.sock = self._create_connection(
                ~~~~~~~~~~~~~~~~~~~~~~~^
        (self.host,self.port), self.timeout, self.source_address)
        ^^^^^^^^^^^^^^^^^^^^^^^^^^^^^^^^^^^^^^^^^^^^^^^^^^^^^^^^^
  File "/usr/local/lib/python3.13/socket.py", line 840, in create_connection
    for res in getaddrinfo(host, port, 0, SOCK_STREAM):
               ~~~~~~~~~~~^^^^^^^^^^^^^^^^^^^^^^^^^^^^
  File "/usr/local/lib/python3.13/socket.py", line 975, in getaddrinfo
    for res in _socket.getaddrinfo(host, port, family, type, proto, flags):
               ~~~~~~~~~~~~~~~~~~~^^^^^^^^^^^^^^^^^^^^^^^^^^^^^^^^^^^^^^^^
socket.gaierror: [Errno -3] Temporary failure in name resolution

During handling of the above exception, another exception occurred:

Traceback (most recent call last):
  File "/home/igor/Documents/code/projects/erstehaus/.venv/lib/python3.13/site-packages/geopy/adapters.py", line 298, in get_text
    page = self.urlopen(req, timeout=timeout)
  File "/usr/local/lib/python3.13/urllib/request.py", line 489, in open
    response = self._open(req, data)
  File "/usr/local/lib/python3.13/urllib/request.py", line 506, in _open
    result = self._call_chain(self.handle_open, protocol, protocol +
                              '_open', req)
  File "/usr/local/lib/python3.13/urllib/request.py", line 466, in _call_chain
    result = func(*args)
  File "/usr/local/lib/python3.13/urllib/request.py", line 1367, in https_open
    return self.do_open(http.client.HTTPSConnection, req,
           ~~~~~~~~~~~~^^^^^^^^^^^^^^^^^^^^^^^^^^^^^^^^^^
                        context=self._context)
                        ^^^^^^^^^^^^^^^^^^^^^^
  File "/usr/local/lib/python3.13/urllib/request.py", line 1322, in do_open
    raise URLError(err)
urllib.error.URLError: <urlopen error [Errno -3] Temporary failure in name resolution>

During handling of the above exception, another exception occurred:

Traceback (most recent call last):
  File "/home/igor/Documents/code/projects/erstehaus/.venv/lib/python3.13/site-packages/django/core/handlers/exception.py", line 55, in inner
    response = get_response(request)
  File "/home/igor/Documents/code/projects/erstehaus/.venv/lib/python3.13/site-packages/django/core/handlers/base.py", line 197, in _get_response
    response = wrapped_callback(request, *callback_args, **callback_kwargs)
  File "/home/igor/Documents/code/projects/erstehaus/home/views.py", line 33, in home
    lat, lon = get_office_coordinates()
               ~~~~~~~~~~~~~~~~~~~~~~^^
  File "/home/igor/Documents/code/projects/erstehaus/home/views.py", line 26, in get_office_coordinates
    location = geolocator.geocode(page_content.address)
  File "/home/igor/Documents/code/projects/erstehaus/.venv/lib/python3.13/site-packages/geopy/geocoders/nominatim.py", line 297, in geocode
    return self._call_geocoder(url, callback, timeout=timeout)
           ~~~~~~~~~~~~~~~~~~~^^^^^^^^^^^^^^^^^^^^^^^^^^^^^^^^
  File "/home/igor/Documents/code/projects/erstehaus/.venv/lib/python3.13/site-packages/geopy/geocoders/base.py", line 368, in _call_geocoder
    result = self.adapter.get_json(url, timeout=timeout, headers=req_headers)
  File "/home/igor/Documents/code/projects/erstehaus/.venv/lib/python3.13/site-packages/geopy/adapters.py", line 287, in get_json
    text = self.get_text(url, timeout=timeout, headers=headers)
  File "/home/igor/Documents/code/projects/erstehaus/.venv/lib/python3.13/site-packages/geopy/adapters.py", line 324, in get_text
    raise GeocoderServiceError(message)
geopy.exc.GeocoderServiceError: [Errno -3] Temporary failure in name resolution
"GET / HTTP/1.1" 500 174047
